const asyncHandler = (requestHandler) => {
    return (req, res, next) => {
        Promise.resolve(requestHandler(req, res, next)).catch((err) => next(err))
    }
}


export { asyncHandler }



 // try catch method 
 // 1- handle error in the middleware function itself by using 
 //'next(error)' if we want to pass control to the next middleware
// const asyncHandler = () => {}
// const asyncHandler = (func) => () => {}
// const asyncHandler = (func) => async () => {}


// const asyncHandler = (fn) => async (req, res, next) => {
//     try {
//         await fn(req, res, next)
//     } catch (error) {
//         res.status(err.code || 500).json({
//             success: false,
//             message: err.message
//         })
//     }
// }